Workbook

Sheet TCT
A1: TỔNG CÔNG TY ĐẦU TƯ | G1: CỘNG HÒA XÃ HỘI CHỦ NGHĨA VIỆT NAM
A2: PHÁT TRIỂN ĐÔ THỊ - CTCP | G2: Độc Lập - Tự Do - Hạnh Phúc
G3: Thanh Hóa ngày 15 tháng 02 năm 2025
A4: TỔNG HỢP PHẠT NỘI QUY KHỐI VĂN PHÒNG THÁNG 01/2025
A6: TT | B6: Số QĐ | C6: Ngày | D6: Mã nhân viên | E6: Họ và tên | F6: Nơi làm việc | G6: Nội dung vi phạm | H6: Mức phạt | I6: Mức hạ loại | J6: Mức bồi thường | L6: Tổng phạt | M6: Ghi chú
A7: 1 | B7: 3 | C7: 45661 | D7: NV0376 | E7: Lê Bá Long | F7: TBP Hậu cần - P. KHHC&KT | G7: Sau khi triển khai kiểm kê ở các kho đã không kiểm tra, kiểm soát lại thông tin sản phẩm của các kho. Không kiểm soát lại số liệu, thông tin sản phẩm của bảng tổng hợp trước khi chuyển cho Ban kinh doanh dẫn đến việc xuất nhầm ở các kho và trực tiếp xuất hàng sai không theo thông báo số 483/TB -TCT ngày 09 tháng 08 năm 2024 của Tổng công ty | H7: 400000 | L7: =H7+J7 -> 400000 | M7: Trừ từ tháng 12/2024 đến 9/2025 (mỗi tháng 400.000 đồng)
A8: 2 | B8: 4 | C8: 45661 | D8: NV0047 | E8: Bùi Đức Tâm | F8: Thủ kho thành phẩm - P. KHHC&KT | G8: Thực hiện sai chỉ đạo khi kiểm kê, kiểm đếm hàng khoanh vùng tại Kho Phân xưởng 1- Nhà máy 2, có những mã ngày sản xuất không có trong thông báo số 483/TB-TCT, dẫn đến xuất nhầm hàng khoanh vùng không đúng theo thông báo số 483/TB - TCT ngày 09 tháng 08 năm 2024 của Tổng công ty | H8: 200000 | L8: =H8+J8 -> 200000 | M8: Trừ từ tháng 12/2024 đến 9/2025 (mỗi tháng 200.000 đồng)
A9: 3 | B9: 5 | C9: 45661 | D9: NV0007 | E9: Đỗ Thị Phương | F9: Thủ kho thành phẩm - P. KHHC&KT | G9: Thực hiện sai chỉ đạo khi kiểm kê, kiểm đếm hàng khoanh vùng tại Kho Quảng Hưng, có những mã ngày sản xuất không có trong thông báo số 483/TB-TCT, dẫn đến xuất nhầm hàng khoanh vùng không đúng theo thông báo số 483/TB - TCT ngày 09 tháng 08 năm 2024 của Tổng công ty | H9: 200000 | L9: =H9+J9 -> 200000 | M9: Trừ từ tháng 12/2024 đến 9/2025 (mỗi tháng 200.000 đồng)
A10: 4 | B10: 6 | C10: 45661 | D10: NV0693 | E10: Nguyễn Hữu Hải | F10: Thủ kho thành phẩm - P. KHHC&KT | G10: Thực hiện sai chỉ đạo khi kiểm kê, kiểm đếm hàng khoanh vùng tại Kho Cảng 2, có những mã ngày sản xuất không có trong thông báo số 483/TB-TCT, dẫn đến xuất nhầm hàng khoanh vùng không đúng theo thông báo số 483/TB - TCT ngày 09 tháng 08 năm 2024 của Tổng công ty. | H10: 200000 | L10: =H10+J10 -> 200000 | M10: Trừ từ tháng 12/2024 đến 9/2025 (mỗi tháng 200.000 đồng)
A11: 5 | B11: 7 | C11: 45661 | D11: NV1071 | E11: Nguyễn Thăng Hệ | F11: TBP Thanh tra | G11: Thực hiện sai quy trình xử lý vi phạm nội quy lao động, không tổ chức họp xử lý kỷ luật và thông báo mức độ vi phạm cho người lao động, yêu cầu bồi thường vật chất chưa dân chủ, trung thực, khách quan trước khi tham mưu trình Tổng giám đốc | H11: 300000 | L11: =H11+J11 -> 300000 | M11: Trừ từ tháng 12/2024 đến 9/2025 (mỗi tháng 300.000 đồng)
A12: Tổng cộng: | H12: =SUM(H7:H11) -> 1300000 | J12: =SUM(J7:J11) -> 0 | L12: =SUM(L7:L11) -> 1300000
A13: Bằng chữ: | E13: =[1]!vnd(L12) -> #NAME?
B15: P TỔ CHỨC | J15: NGƯỜI LẬP
B19: Nguyễn Văn Dương | J19: Đỗ Thị Thu Hương
A25: TỔNG CÔNG TY ĐẦU TƯ | G25: CỘNG HÒA XÃ HỘI CHỦ NGHĨA VIỆT NAM
A26: PHÁT TRIỂN ĐÔ THỊ - CTCP | G26: Độc Lập - Tự Do - Hạnh Phúc
G27: Thanh Hóa ngày 15 tháng 03 năm 2025
A28: TỔNG HỢP PHẠT NỘI QUY KHỐI VĂN PHÒNG THÁNG 02/2025
A30: TT | B30: Số QĐ | C30: Ngày | D30: Mã nhân viên | E30: Họ và tên | F30: Nơi làm việc | G30: Nội dung vi phạm | H30: Mức phạt | I30: Mức hạ loại | J30: Mức bồi thường | K30: Điểm trừ | L30: Tổng phạt | M30: Ghi chú
A31: 1 | B31: 3 | C31: 45661 | D31: NV0376 | E31: Lê Bá Long | F31: TBP Hậu cần - P. KHHC&KT | G31: Sau khi triển khai kiểm kê ở các kho đã không kiểm tra, kiểm soát lại thông tin sản phẩm của các kho. Không kiểm soát lại số liệu, thông tin sản phẩm của bảng tổng hợp trước khi chuyển cho Ban kinh doanh dẫn đến việc xuất nhầm ở các kho và trực tiếp xuất hàng sai không theo thông báo số 483/TB -TCT ngày 09 tháng 08 năm 2024 của Tổng công ty | H31: 400000 | L31: =H31+J31 -> 400000 | M31: Trừ từ tháng 12/2024 đến 9/2025 (mỗi tháng 400.000 đồng)
A32: 2 | B32: 4 | C32: 45661 | D32: NV0047 | E32: Bùi Đức Tâm | F32: Thủ kho thành phẩm - P. KHHC&KT | G32: Thực hiện sai chỉ đạo khi kiểm kê, kiểm đếm hàng khoanh vùng tại Kho Phân xưởng 1- Nhà máy 2, có những mã ngày sản xuất không có trong thông báo số 483/TB-TCT, dẫn đến xuất nhầm hàng khoanh vùng không đúng theo thông báo số 483/TB - TCT ngày 09 tháng 08 năm 2024 của Tổng công ty | H32: 200000 | L32: =H32+J32 -> 200000 | M32: Trừ từ tháng 12/2024 đến 9/2025 (mỗi tháng 200.000 đồng)
A33: 3 | B33: 5 | C33: 45661 | D33: NV0007 | E33: Đỗ Thị Phương | F33: Thủ kho thành phẩm - P. KHHC&KT | G33: Thực hiện sai chỉ đạo khi kiểm kê, kiểm đếm hàng khoanh vùng tại Kho Quảng Hưng, có những mã ngày sản xuất không có trong thông báo số 483/TB-TCT, dẫn đến xuất nhầm hàng khoanh vùng không đúng theo thông báo số 483/TB - TCT ngày 09 tháng 08 năm 2024 của Tổng công ty | H33: 200000 | L33: =H33+J33 -> 200000 | M33: Trừ từ tháng 12/2024 đến 9/2025 (mỗi tháng 200.000 đồng)
A34: 4 | B34: 6 | C34: 45661 | D34: NV0693 | E34: Nguyễn Hữu Hải | F34: Thủ kho thành phẩm - P. KHHC&KT | G34: Thực hiện sai chỉ đạo khi kiểm kê, kiểm đếm hàng khoanh vùng tại Kho Cảng 2, có những mã ngày sản xuất không có trong thông báo số 483/TB-TCT, dẫn đến xuất nhầm hàng khoanh vùng không đúng theo thông báo số 483/TB - TCT ngày 09 tháng 08 năm 2024 của Tổng công ty. | H34: 200000 | L34: =H34+J34 -> 200000 | M34: Trừ từ tháng 12/2024 đến 9/2025 (mỗi tháng 200.000 đồng)
A35: 5 | B35: 7 | C35: 45661 | D35: NV1071 | E35: Nguyễn Thăng Hệ | F35: TBP Thanh tra | G35: Thực hiện sai quy trình xử lý vi phạm nội quy lao động, không tổ chức họp xử lý kỷ luật và thông báo mức độ vi phạm cho người lao động, yêu cầu bồi thường vật chất chưa dân chủ, trung thực, khách quan trước khi tham mưu trình Tổng giám đốc | H35: 300000 | L35: =H35+J35 -> 300000 | M35: Trừ từ tháng 12/2024 đến 9/2025 (mỗi tháng 300.000 đồng)
A36: 6 | B36: 115 | C36: 45709 | D36: NV3323 | E36: Đỗ Đức Nam | F36: Nhân viên QC - Ban thanh tra - kiểm soát | G36: Vào hồi 16h ngày 15/2/2025. Trong quá trình nhập nhiên liệu (dầu) tại kho PX2. Do tính chất công việc nên không thực hiện giám sát hết quá trình nhập nhiên liệu tại kho. Để thủ kho xả dầu quá dung tích chứa của bồn làm tràn dầu ra ngoài gây thiệt hại cho cty | L36: =H36+J36 -> 0 | M36: Cảnh cáo
A45: Tổng cộng: | H45: =SUM(H31:H44) -> 1300000 | J45: =SUM(J31:J44) -> 0 | L45: =SUM(L31:L44) -> 1300000
A46: Bằng chữ: | E46: =[2]!vnd(L45) -> #NAME?
B48: P TỔ CHỨC | J48: NGƯỜI LẬP
B52: Nguyễn Văn Dương | J52: Đỗ Thị Thu Hương
A60: TỔNG CÔNG TY ĐẦU TƯ | G60: CỘNG HÒA XÃ HỘI CHỦ NGHĨA VIỆT NAM
A61: PHÁT TRIỂN ĐÔ THỊ - CTCP | G61: Độc Lập - Tự Do - Hạnh Phúc
G62: Thanh Hóa ngày 15 tháng 04 năm 2025
A63: TỔNG HỢP PHẠT NỘI QUY KHỐI VĂN PHÒNG THÁNG 03/2025
A65: TT | B65: Số QĐ | C65: Ngày | D65: Mã nhân viên | E65: Họ và tên | F65: Nơi làm việc | G65: Nội dung vi phạm | H65: Mức phạt | I65: Mức hạ loại | J65: Mức bồi thường | K65: Điểm trừ | L65: Tổng phạt | M65: Ghi chú
A66: 1 | B66: 3 | C66: 45661 | D66: NV0376 | E66: Lê Bá Long | F66: TBP Hậu cần - P. KHHC&KT | G66: Sau khi triển khai kiểm kê ở các kho đã không kiểm tra, kiểm soát lại thông tin sản phẩm của các kho. Không kiểm soát lại số liệu, thông tin sản phẩm của bảng tổng hợp trước khi chuyển cho Ban kinh doanh dẫn đến việc xuất nhầm ở các kho và trực tiếp xuất hàng sai không theo thông báo số 483/TB -TCT ngày 09 tháng 08 năm 2024 của Tổng công ty | H66: 400000 | L66: =H66+J66 -> 400000 | M66: Trừ từ tháng 12/2024 đến 9/2025 (mỗi tháng 400.000 đồng)
A67: 2 | B67: 4 | C67: 45661 | D67: NV0047 | E67: Bùi Đức Tâm | F67: Thủ kho thành phẩm - P. KHHC&KT | G67: Thực hiện sai chỉ đạo khi kiểm kê, kiểm đếm hàng khoanh vùng tại Kho Phân xưởng 1- Nhà máy 2, có những mã ngày sản xuất không có trong thông báo số 483/TB-TCT, dẫn đến xuất nhầm hàng khoanh vùng không đúng theo thông báo số 483/TB - TCT ngày 09 tháng 08 năm 2024 của Tổng công ty | H67: 200000 | L67: =H67+J67 -> 200000 | M67: Trừ từ tháng 12/2024 đến 9/2025 (mỗi tháng 200.000 đồng)
A68: 3 | B68: 5 | C68: 45661 | D68: NV0007 | E68: Đỗ Thị Phương | F68: Thủ kho thành phẩm - P. KHHC&KT | G68: Thực hiện sai chỉ đạo khi kiểm kê, kiểm đếm hàng khoanh vùng tại Kho Quảng Hưng, có những mã ngày sản xuất không có trong thông báo số 483/TB-TCT, dẫn đến xuất nhầm hàng khoanh vùng không đúng theo thông báo số 483/TB - TCT ngày 09 tháng 08 năm 2024 của Tổng công ty | H68: 200000 | L68: =H68+J68 -> 200000 | M68: Trừ từ tháng 12/2024 đến 9/2025 (mỗi tháng 200.000 đồng)
A69: 4 | B69: 6 | C69: 45661 | D69: NV0693 | E69: Nguyễn Hữu Hải | F69: Thủ kho thành phẩm - P. KHHC&KT | G69: Thực hiện sai chỉ đạo khi kiểm kê, kiểm đếm hàng khoanh vùng tại Kho Cảng 2, có những mã ngày sản xuất không có trong thông báo số 483/TB-TCT, dẫn đến xuất nhầm hàng khoanh vùng không đúng theo thông báo số 483/TB - TCT ngày 09 tháng 08 năm 2024 của Tổng công ty. | H69: 200000 | L69: =H69+J69 -> 200000 | M69: Trừ từ tháng 12/2024 đến 9/2025 (mỗi tháng 200.000 đồng)
A70: 5 | B70: 7 | C70: 45661 | D70: NV1071 | E70: Nguyễn Thăng Hệ | F70: TBP Thanh tra | G70: Thực hiện sai quy trình xử lý vi phạm nội quy lao động, không tổ chức họp xử lý kỷ luật và thông báo mức độ vi phạm cho người lao động, yêu cầu bồi thường vật chất chưa dân chủ, trung thực, khách quan trước khi tham mưu trình Tổng giám đốc | H70: 300000 | L70: =H70+J70 -> 300000 | M70: Trừ từ tháng 12/2024 đến 9/2025 (mỗi tháng 300.000 đồng)
A71: 6 | B71: 96 | C71: 46009 | D71: NV4119 | E71: Hoàng Ngọc Dương | F71: Nhân viên thủ kho nguyên liệu - Phòng kế toán | G71: Thiếu tinh thần trách nhiệm trong quá trình nhập hàng tại kho, kiểm soát lượng hàng tồn kho chưa tốt dẫn đến đề nghị nhập hàng quá với dung tích chứa của bồn, khi xả nhiên liệu từ xe tec xuống bồn làm tràn dầu ra ngoài gây thiệt hại tài sản của công ty | H71: 500000 | J71: 600000 | K71: 20 | L71: =H71+J71 -> 1100000
...

Sheet CT
E1: CÔNG TY CỔ PHẦN | G1: CỘNG HÒA XÃ HỘI CHỦ NGHĨA VIỆT NAM
E2: ĐẦU TƯ PHÁT TRIỂN VICENZA | G2: Độc Lập - Tự Do - Hạnh Phúc
H3: Thanh Hóa, ngày 15 tháng 02 năm 2025
A4: TỔNG HỢP PHẠT NỘI QUY KHỐI VĂN PHÒNG THÁNG 01/2025
A5: TT | B5: Số QĐ | C5: Ngày | D5: Mã nhân viên | E5: Họ và tên | F5: Nơi làm việc | G5: Nội dung vi phạm | H5: Mức phạt | I5: Mức hạ loại | J5: Mức bồi thường | L5: Tổng phạt | M5: Ghi chú
A6: 1 | B6: 8 | C6: 45661 | D6: NV0086 | E6: Trần Văn Kỳ | F6: NV Phòng TCHC | G6: Liên đới trách nhiệm trong việc thực hiện chưa đúng quy trình xử lý vi phạm nội quy lao động | H6: 100000 | L6: =H6+J6 -> 100000 | M6: Trừ từ tháng 12/2024 đến 9/2025 (mỗi tháng 100.000 đồng)
A7: Tổng cộng: | H7: =SUM(H6:H6) -> 100000 | J7: =SUM(J6:J6) -> 0 | L7: =SUM(L6:L6) -> 100000
A8: Bằng chữ: | D8: =[1]!vnd(L7) -> #NAME?
B10: P TỔ CHỨC | J10: NGƯỜI LẬP
B14: Nguyễn Văn Dương | J14: Đỗ Thị Thu Hương
E23: CÔNG TY CỔ PHẦN | G23: CỘNG HÒA XÃ HỘI CHỦ NGHĨA VIỆT NAM
E24: ĐẦU TƯ PHÁT TRIỂN VICENZA | G24: Độc Lập - Tự Do - Hạnh Phúc
H25: Thanh Hóa, ngày 15 tháng 03 năm 2025
A26: TỔNG HỢP PHẠT NỘI QUY KHỐI VĂN PHÒNG THÁNG 02/2025
A27: TT | B27: Số QĐ | C27: Ngày | D27: Mã nhân viên | E27: Họ và tên | F27: Nơi làm việc | G27: Nội dung vi phạm | H27: Mức phạt | I27: Mức hạ loại | J27: Mức bồi thường | K27: Điểm trừ | L27: Tổng phạt | M27: Ghi chú
A28: 1 | B28: 8 | C28: 45661 | D28: NV0086 | E28: Trần Văn Kỳ | F28: NV Phòng TCHC | G28: Liên đới trách nhiệm trong việc thực hiện chưa đúng quy trình xử lý vi phạm nội quy lao động | H28: 100000 | L28: =H28+J28 -> 100000 | M28: Trừ từ tháng 12/2024 đến 9/2025 (mỗi tháng 100.000 đồng)
A29: 2 | L29: =H29+J29 -> 0
L30: =H30+J30 -> 0
L31: =H31+J31 -> 0
L32: =H32+J32 -> 0
L33: =H33+J33 -> 0
L34: =H34+J34 -> 0
L35: =H35+J35 -> 0
L36: =H36+J36 -> 0
A37: Tổng cộng: | H37: =SUM(H28:H36) -> 100000 | J37: =SUM(J28:J36) -> 0 | L37: =SUM(L28:L36) -> 100000
A38: Bằng chữ: | D38: =[1]!vnd(L37) -> #NAME?
B40: P TỔ CHỨC | J40: NGƯỜI LẬP
B44: Nguyễn Văn Dương | J44: Đỗ Thị Thu Hương
E49: CÔNG TY CỔ PHẦN | G49: CỘNG HÒA XÃ HỘI CHỦ NGHĨA VIỆT NAM
E50: ĐẦU TƯ PHÁT TRIỂN VICENZA | G50: Độc Lập - Tự Do - Hạnh Phúc
H51: Thanh Hóa, ngày 15 tháng 04 năm 2025
A52: TỔNG HỢP PHẠT NỘI QUY KHỐI VĂN PHÒNG THÁNG 03/2025
A53: TT | B53: Số QĐ | C53: Ngày | D53: Mã nhân viên | E53: Họ và tên | F53: Nơi làm việc | G53: Nội dung vi phạm | H53: Mức phạt | I53: Mức hạ loại | J53: Mức bồi thường | K53: Điểm trừ | L53: Tổng phạt | M53: Ghi chú
A54: 1 | B54: 8 | C54: 45661 | D54: NV0086 | E54: Trần Văn Kỳ | F54: NV Phòng TCHC | G54: Liên đới trách nhiệm trong việc thực hiện chưa đúng quy trình xử lý vi phạm nội quy lao động | H54: 100000 | L54: =H54+J54 -> 100000 | M54: Trừ từ tháng 12/2024 đến 9/2025 (mỗi tháng 100.000 đồng)
A55: 2 | B55: 97 | C55: 45706 | D55: NV2579 | E55: Lê Văn Chính | F55: Nhân viên Bảo vệ | G55: Chấp hành không nghiêm nội quy lao động (Ngủ trong giờ làm việc) | H55: 500000 | K55: 15 | L55: =H55+J55 -> 500000
A56: 3 | B56: 179 | C56: 45721 | D56: NV0386 | E56: Lê Đình Tuấn | F56: Nhân viên Bảo vệ | G56: Chấp hành không nghiêm nội quy lao động (Trực cổng không đúng vị trí, lợi dụng thời gian nghỉ trưa nằm nghỉ tại phòng thủ kho cổng ốp). | K56: 5 | L56: =H56+J56 -> 0
A57: Tổng cộng: | H57: =SUM(H54:H56) -> 600000 | J57: =SUM(J54:J56) -> 0 | L57: =SUM(L54:L56) -> 600000
A58: Bằng chữ: | D58: Sáu trăm nghìn đồng.
B60: P TỔ CHỨC | J60: NGƯỜI LẬP
B64: Nguyễn Văn Dương | J64: Lê Thị Diễm
...

Sheet PXSX1
E1: CÔNG TY CỔ PHẦN | G1: CỘNG HÒA XÃ HỘI CHỦ NGHĨA VIỆT NAM
E2: ĐẦU TƯ PHÁT TRIỂN VICENZA | G2: Độc Lập - Tự Do - Hạnh Phúc
H3: Thanh Hóa, ngày 15 tháng 02 năm 2025
A4: TỔNG HỢP PHẠT NỘI QUY NHÀ MÁY 1 THÁNG 01/2025
A5: TT | B5: Số QĐ | C5: Ngày | D5: Mã nhân viên | E5: Họ và tên | F5: Nơi làm việc | G5: Nội dung vi phạm | H5: Mức phạt | I5: Mức hạ loại | J5: Mức bồi thường | L5: Tổng phạt | M5: Ghi chú
A6: 1 | L6: =H6+J6 -> 0
A7: 2 | L7: =H7+J7 -> 0
A8: 3 | L8: =H8+J8 -> 0
A9: 4 | L9: =H9+J9 -> 0
A10: 5 | L10: =H10+J10 -> 0
A11: 6 | L11: =H11+J11 -> 0
A12: 7 | L12: =H12+J12 -> 0
A13: 8 | L13: =H13+J13 -> 0
A14: 9 | L14: =H14+J14 -> 0
A15: 10 | L15: =H15+J15 -> 0
A16: 11 | L16: =H16+J16 -> 0
A17: 12 | L17: =H17+J17 -> 0 | N17: =SUM(H14:H17) -> 0
A18: Tổng cộng: | H18: =SUM(H6:H17) -> 0 | J18: =SUM(J6:J17) -> 0 | L18: =SUM(L6:L17) -> 0
A19: Bằng chữ: | D19: =[1]!vnd(L18) -> #NAME?
B21: P TỔ CHỨC | J21: NGƯỜI LẬP
B25: Nguyễn Văn Dương | J25: Đỗ Thị Thu Hương
E30: CÔNG TY CỔ PHẦN | G30: CỘNG HÒA XÃ HỘI CHỦ NGHĨA VIỆT NAM
E31: ĐẦU TƯ PHÁT TRIỂN VICENZA | G31: Độc Lập - Tự Do - Hạnh Phúc
H32: Thanh Hóa, ngày 15 tháng 03 năm 2025
A33: TỔNG HỢP PHẠT NỘI QUY PXSX 1 THÁNG 02/2025
A34: TT | B34: Số QĐ | C34: Ngày | D34: Mã nhân viên | E34: Họ và tên | F34: Nơi làm việc | G34: Nội dung vi phạm | H34: Mức phạt | I34: Mức hạ loại | J34: Mức bồi thường | K34: Điểm trừ | L34: Tổng phạt | M34: Ghi chú
A35: 1 | L35: =H35+J35 -> 0
A36: 2 | L36: =H36+J36 -> 0
A37: 3 | L37: =H37+J37 -> 0
A38: 4 | L38: =H38+J38 -> 0
A39: 5 | L39: =H39+J39 -> 0
A40: 6 | L40: =H40+J40 -> 0
A41: 7 | L41: =H41+J41 -> 0
A42: 8 | L42: =H42+J42 -> 0
A43: 9 | L43: =H43+J43 -> 0
A44: 10 | L44: =H44+J44 -> 0
A45: 11 | L45: =H45+J45 -> 0
A46: 12 | L46: =H46+J46 -> 0 | N46: =SUM(H43:H46) -> 0
A47: Tổng cộng: | H47: =SUM(H35:H46) -> 0 | J47: =SUM(J35:J46) -> 0 | L47: =SUM(L35:L46) -> 0
A48: Bằng chữ: | D48: =[2]!vnd(L47) -> #NAME?
...

Sheet PXSX2
A1: TỔNG CÔNG TY ĐẦU TƯ | G1: CỘNG HÒA XÃ HỘI CHỦ NGHĨA VIỆT NAM
A2: PHÁT TRIỂN ĐÔ THỊ - CTCP | G2: Độc Lập - Tự Do - Hạnh Phúc
G3: Thanh Hóa ngày 15 tháng 02 năm 2025
A4: TỔNG HỢP PHẠT NỘI QUY NHÀ MÁY 2 THÁNG 01/2025
A5: TT | B5: Số QĐ | C5: Ngày | D5: Mã nhân viên | E5: Họ và tên | F5: Nơi làm việc | G5: Nội dung vi phạm | H5: Mức phạt | I5: Mức hạ loại | J5: Mức bồi thường | L5: Tổng phạt | M5: Ghi chú
A6: 1 | L6: =H6+J6 -> 0
A7: 2 | L7: =H7+J7 -> 0
A8: 3 | L8: =H8+J8 -> 0
A9: 4 | L9: =H9+J9 -> 0
A10: 5 | L10: =H10+J10 -> 0
A11: 6 | L11: =H11+J11 -> 0
A12: 7 | L12: =H12+J12 -> 0
A13: 8 | L13: =H13+J13 -> 0
A14: Tổng cộng: | H14: =SUM(H6:H13) -> 0 | J14: =SUM(J6:J13) -> 0 | L14: =SUM(L6:L13) -> 0
A15: Bằng chữ: | E15: =[2]!vnd(L14) -> #NAME?
B17: P TỔ CHỨC | J17: NGƯỜI LẬP
B21: Nguyễn Văn Dương | J21: Đỗ Thị Thu Hương
A29: TỔNG CÔNG TY ĐẦU TƯ | G29: CỘNG HÒA XÃ HỘI CHỦ NGHĨA VIỆT NAM
A30: PHÁT TRIỂN ĐÔ THỊ - CTCP | G30: Độc Lập - Tự Do - Hạnh Phúc
G31: Thanh Hóa ngày 15 tháng 03 năm 2025
A32: TỔNG HỢP PHẠT NỘI QUY PXSX2 THÁNG 02/2025
A33: TT | B33: Số QĐ | C33: Ngày | D33: Mã nhân viên | E33: Họ và tên | F33: Nơi làm việc | G33: Nội dung vi phạm | H33: Mức phạt | I33: Mức hạ loại | J33: Mức bồi thường | K33: Điểm trừ | L33: Tổng phạt | M33: Ghi chú
A34: 1 | B34: 77 | C34: 45699 | D34: NV1613 | E34: Lê Hữu Thiết | F34: Tổ phó Tổ xe máy Hậu cần - PXSX2 | G34: Vào hồi 15h35 ngày 5/2/2025. Trong quá trình điều khiển phương tiện xe nâng vận chuyển gạch từ cổng vào phân xưởng, do không cẩn thận khi lên dốc làm nghiêng xe đổ 3 palet gạch (15x80); Tổng 261 hộp; sau khi lọc còn 118 hộp A1 và 21 hộp A2; Vỡ chuyển sang phế hủy 122 hộp; Mã TL11-158006A1F20 | J34: =3138000/2 -> 1569000 | L34: =H34+J34 -> 1569000 | M34: Phạt 3tr138 (trừ T2;T3)
A35: 2 | L35: =H35+J35 -> 0
A36: 3 | L36: =H36+J36 -> 0
A37: 4 | L37: =H37+J37 -> 0
A38: 5 | L38: =H38+J38 -> 0
A39: 6 | L39: =H39+J39 -> 0
A40: 7 | L40: =H40+J40 -> 0
A41: 8 | L41: =H41+J41 -> 0
A42: Tổng cộng: | H42: =SUM(H34:H41) -> 0 | J42: =SUM(J34:J41) -> 1569000 | L42: =SUM(L34:L41) -> 1569000
A43: Bằng chữ: | E43: =[2]!vnd(L42) -> #NAME?
B45: P TỔ CHỨC | J45: NGƯỜI LẬP
B49: Nguyễn Văn Dương | J49: Đỗ Thị Thu Hương
A54: TỔNG CÔNG TY ĐẦU TƯ | G54: CỘNG HÒA XÃ HỘI CHỦ NGHĨA VIỆT NAM
A55: PHÁT TRIỂN ĐÔ THỊ - CTCP | G55: Độc Lập - Tự Do - Hạnh Phúc
G56: Thanh Hóa ngày 15 tháng 04 năm 2025
A57: TỔNG HỢP PHẠT NỘI QUY PXSX2 THÁNG 03/2025
A58: TT | B58: Số QĐ | C58: Ngày | D58: Mã nhân viên | E58: Họ và tên | F58: Nơi làm việc | G58: Nội dung vi phạm | H58: Mức phạt | I58: Mức hạ loại | J58: Mức bồi thường | K58: Điểm trừ | L58: Tổng phạt | M58: Ghi chú
A59: 1 | B59: 132 | C59: 45714 | D59: NV4187 | E59: Phạm Văn Sơn | F59: Công nhân Lái xe nâng - DC5 - PXSX2 | G59: Vào hồi 13h40 ngày 25/2/2025. Trong quá trình điều khiển phương tiện xe nâng do thiếu quan sát để càng xe thúc vào phi dầu (Alpha SP220 Castro), làm thủng phi chảy dầu ra ngoài; Số lượng: 13,2 lít (Có biên bản kèm theo). Làm thất thiệt vật tư của công ty | J59: 817000 | K59: 30 | L59: =H59+J59 -> 817000
...

Sheet VIỆT NHẬT
A1: CÔNG TY TNHH KHAI THÁC VÀ CHẾ BIẾN | G1: CỘNG HÒA XÃ HỘI CHỦ NGHĨA VIỆT NAM
A2: KHOÁNG SẢN LIÊN DOANH VIỆT NHẬT | G2: Độc Lập - Tự Do - Hạnh Phúc
G3: Thanh Hóa ngày 15 tháng 02 năm 2025
A4: TỔNG HỢP PHẠT NỘI QUY THÁNG 01/2025
A6: TT | B6: Số QĐ | C6: Ngày | D6: Mã nhân viên | E6: Họ và tên | F6: Nơi làm việc | G6: Nội dung vi phạm | H6: Mức phạt | I6: Mức hạ loại | J6: Mức bồi thường | K6: Điểm trừ | L6: Tổng phạt | M6: Ghi chú
A7: 1 | B7: 36 | C7: 45680 | D7: NV5394 | E7: Nguyễn Văn Tuấn | F7: Lái xe howo | G7: Trong quá trình trút đổ nguyên liệu không cẩn thận khi nâng ben làm xe bị nghiêng và đổ, làm móp méo cabin, vỡ kính cửa bên lái | H7: 0 | I7: 0 | J7: 2380000 | K7: 20 | L7: =H7+J7 -> 2380000
A8: Tổng cộng: | H8: =SUM(H7:H7) -> 0 | J8: =SUM(J7:J7) -> 2380000 | L8: =SUM(L7:L7) -> 2380000
A9: Bằng chữ: | E9: =[1]!vnd(L8) -> #NAME?
B11: P TỔ CHỨC | J11: NGƯỜI LẬP
B15: Nguyễn Văn Dương | J15: Đỗ Thị Thu Hương
A24: CÔNG TY TNHH KHAI THÁC VÀ CHẾ BIẾN | G24: CỘNG HÒA XÃ HỘI CHỦ NGHĨA VIỆT NAM
A25: KHOÁNG SẢN LIÊN DOANH VIỆT NHẬT | G25: Độc Lập - Tự Do - Hạnh Phúc
G26: Thanh Hóa ngày 15 tháng 03 năm 2025
A27: TỔNG HỢP PHẠT NỘI QUY THÁNG 02/2025
A29: TT | B29: Số QĐ | C29: Ngày | D29: Mã nhân viên | E29: Họ và tên | F29: Nơi làm việc | G29: Nội dung vi phạm | H29: Mức phạt | I29: Mức hạ loại | J29: Mức bồi thường | K29: Điểm trừ | L29: Tổng phạt | M29: Ghi chú
A30: 1 | B30: 114 | C30: 45709 | D30: NV5273 | E30: Lê Bá Cần | F30: NV Lái xe mỏ - Đội xe máy - Ban đầu tư và khai thác | G30: Thiếu kiểm soát trong việc theo dõi số km vận hành của xe tải BKS: 36H-06891, dẫn đến thay dầu máy trước định kỳ km vận hành của phương tiện, gây lãng phí cho cty | H30: 0 | I30: 0 | K30: 5 | L30: =H30+J30 -> 0 | M30: Cảnh cáo
A31: Tổng cộng: | H31: =SUM(H30:H30) -> 0 | J31: =SUM(J30:J30) -> 0 | L31: =SUM(L30:L30) -> 0
A32: Bằng chữ: | E32: =[1]!vnd(L31) -> #NAME?
B34: P TỔ CHỨC | J34: NGƯỜI LẬP
B38: Nguyễn Văn Dương | J38: Đỗ Thị Thu Hương
A43: CÔNG TY TNHH KHAI THÁC VÀ CHẾ BIẾN | G43: CỘNG HÒA XÃ HỘI CHỦ NGHĨA VIỆT NAM
A44: KHOÁNG SẢN LIÊN DOANH VIỆT NHẬT | G44: Độc Lập - Tự Do - Hạnh Phúc
G45: Thanh Hóa ngày 15 tháng 04 năm 2025
A46: TỔNG HỢP PHẠT NỘI QUY THÁNG 03/2025
A48: TT | B48: Số QĐ | C48: Ngày | D48: Mã nhân viên | E48: Họ và tên | F48: Nơi làm việc | G48: Nội dung vi phạm | H48: Mức phạt | I48: Mức hạ loại | J48: Mức bồi thường | K48: Điểm trừ | L48: Tổng phạt | M48: Ghi chú
A49: 1 | B49: 105 | C49: 45708 | D49: NV5019 | E49: Nguyễn Xuân Thủy | F49: NV Lái xe mỏ - Tổ đội xe máy - Ban đầu tư và khai thác | G49: Vào ngày 19/2/2025 khi đưa xe về đội sửa chữa để khắc phục xe trong tình trạng bị rách thùng (Theo đánh giá thùng xe bị răng của gầu máy xúc đào cào rách). Nhưng lái xe khẳng định không xác định thời gian, điểm điểm và người điều khiển phương tiện (Máy xúc đào) khi vận hành | H49: 500000 | I49: 0 | K49: 20 | L49: =H49+J49 -> 500000
A50: Tổng cộng: | H50: =SUM(H49:H49) -> 500000 | J50: =SUM(J49:J49) -> 0 | L50: =SUM(L49:L49) -> 500000
A51: Bằng chữ: | E51: =[1]!vnd(L50) -> #NAME?
B53: P TỔ CHỨC | J53: NGƯỜI LẬP
B57: Nguyễn Văn Dương | J57: Đỗ Thị Thu Hương
A59: CÔNG TY TNHH KHAI THÁC VÀ CHẾ BIẾN | G59: CỘNG HÒA XÃ HỘI CHỦ NGHĨA VIỆT NAM
A60: KHOÁNG SẢN LIÊN DOANH VIỆT NHẬT | G60: Độc Lập - Tự Do - Hạnh Phúc
G61: Thanh Hóa ngày 15 tháng 04 năm 2025
A62: TỔNG HỢP PHẠT NỘI QUY THÁNG 03/2025
A64: TT | B64: Số QĐ | C64: Ngày | D64: Mã nhân viên | E64: Họ và tên | F64: Nơi làm việc | G64: Nội dung vi phạm | H64: Mức phạt | I64: Mức hạ loại | J64: Mức bồi thường | K64: Điểm trừ | L64: Tổng phạt | M64: Ghi chú
A65: 1 | B65: 105 | C65: 45708 | D65: NV5019 | E65: Nguyễn Xuân Thủy | F65: NV Lái xe mỏ - Tổ đội xe máy - Ban đầu tư và khai thác | G65: Vào ngày 19/2/2025 khi đưa xe về đội sửa chữa để khắc phục xe trong tình trạng bị rách thùng (Theo đánh giá thùng xe bị răng của gầu máy xúc đào cào rách). Nhưng lái xe khẳng định không xác định thời gian, điểm điểm và người điều khiển phương tiện (Máy xúc đào) khi vận hành | H65: 500000 | I65: 0 | K65: 20 | L65: =H65+J65 -> 500000
A66: Tổng cộng: | H66: =SUM(H65:H65) -> 500000 | J66: =SUM(J65:J65) -> 0 | L66: =SUM(L65:L65) -> 500000
A67: Bằng chữ: | E67: =[1]!vnd(L66) -> #NAME?
B69: P TỔ CHỨC | J69: NGƯỜI LẬP
B73: Nguyễn Văn Dương | J73: Đỗ Thị Thu Hương
...

Sheet TỔNG HỢP
A2: TỔNG CÔNG TY ĐẦU TƯ | K2: CỘNG HÒA XÃ HỘI CHỦ NGHĨA VIỆT NAM
A3: PHÁT TRIỂN ĐÔ THỊ - CTCP | K3: Độc Lập - Tự Do - Hạnh Phúc
A4: CÔNG TY CỔ PHẦN | L4: Thanh hóa ngày 01 tháng 01 năm 2025
A5: ĐẦU TƯ PHÁT TRIỂN VICENZA
A8: TỔNG HỢP PHẠT NỘI QUY NĂM 2025
A9: THÁNG | B9: VĂN PHÒNG TCT | E9: VĂN PHÒNG VCZ | H9: NHÀ MÁY 1 | K9: NHÀ MÁY 2 | N9: VIỆT NHẬT | Q9: TỔNG CỘNG
B10: Mức phạt | C10: Mức bồi thường | D10: Tổng | E10: Mức phạt | F10: Mức bồi thường | G10: Tổng | H10: Mức phạt | I10: Mức bồi thường | J10: Tổng | K10: Mức phạt | L10: Mức bồi thường | M10: Tổng | N10: Mức phạt | O10: Mức bồi thường | P10: Tổng
A11: 01/2025 | B11: =TCT!H12 -> 1300000 | C11: 0 | D11: =B11+C11 -> 1300000 | E11: =CT!H7 -> 100000 | F11: 0 | G11: =E11+F11 -> 100000 | H11: 0 | I11: 0 | J11: =H11+I11 -> 0 | K11: 0 | L11: 0 | M11: =K11+L11 -> 0 | N11: 0 | O11: ='VIỆT NHẬT'!J8 -> 2380000 | P11: =N11+O11 -> 2380000 | Q11: =D11+G11+J11+M11+P11 -> 3780000
A12: 02/2025 | D12: =B12+C12 -> 0 | G12: =E12+F12 -> 0 | J12: =H12+I12 -> 0 | M12: =K12+L12 -> 0 | P12: =N12+O12 -> 0 | Q12: =D12+G12+J12+M12+P12 -> 0
A13: 03/2025 | B13: 2800000 | C13: 2810000 | D13: =B13+C13 -> 5610000 | E13: 600000 | G13: =E13+F13 -> 600000 | H13: 1800000 | J13: =H13+I13 -> 1800000 | K13: 2900000 | L13: 7490000 | M13: =K13+L13 -> 10390000 | N13: 500000 | P13: =N13+O13 -> 500000 | Q13: =D13+G13+J13+M13+P13 -> 18900000
A14: 04/2025 | B14: =+TCT!H114 -> 12800000 | C14: =+TCT!J114 -> 1200000 | D14: =B14+C14 -> 14000000 | E14: =+CT!L85 -> 100000 | G14: =E14+F14 -> 100000 | H14: =+PXSX1!L97 -> 1200000 | J14: =H14+I14 -> 1200000 | K14: =+PXSX2!L95 -> 800000 | M14: =K14+L14 -> 800000 | P14: =N14+O14 -> 0 | Q14: =D14+G14+J14+M14+P14 -> 16100000
A15: 05/2025 | B15: =+TCT!H144 -> 4466666.7 | C15: =+TCT!J144 -> 1200000 | D15: =B15+C15 -> 5666666.7 | E15: =+CT!H111 -> 1100000 | F15: =+CT!J111 -> 0 | G15: =E15+F15 -> 1100000 | H15: =+PXSX1!H133 -> 4100000 | I15: =+PXSX1!J133 -> 0 | J15: =H15+I15 -> 4100000 | K15: =+PXSX2!H134 -> 3800000 | L15: =+PXSX2!J134 -> 0 | M15: =K15+L15 -> 3800000 | P15: =N15+O15 -> 0 | Q15: =D15+G15+J15+M15+P15 -> 14666667
A16: 06/2025 | B16: =+TCT!H178 -> 4316666.7 | C16: =+TCT!J178 -> 0 | D16: =B16+C16 -> 4316666.7 | E16: =+CT!H137 -> 600000 | F16: =+CT!J137 -> 0 | G16: =E16+F16 -> 600000 | H16: =+PXSX1!H171 -> 1000000 | I16: =+PXSX1!J171 -> 0 | J16: =H16+I16 -> 1000000 | K16: =+PXSX2!H171 -> 1400000 | L16: =+PXSX2!J171 -> 0 | M16: =K16+L16 -> 1400000 | P16: =N16+O16 -> 0 | Q16: =D16+G16+J16+M16+P16 -> 7316666.7
A17: 07/2025 | B17: 4716667 | C17: 453000 | D17: =B17+C17 -> 5169667 | E17: 1600000 | F17: 3768500 | G17: =E17+F17 -> 5368500 | H17: 6500000 | J17: =H17+I17 -> 6500000 | K17: 9600000 | M17: =K17+L17 -> 9600000 | P17: =N17+O17 -> 0 | Q17: =D17+G17+J17+M17+P17 -> 26638167
A18: 08/2025 | B18: 800000 | D18: =B18+C18 -> 800000 | E18: 100000 | F18: 825000 | G18: =E18+F18 -> 925000 | J18: =H18+I18 -> 0 | K18: 1500000 | M18: =K18+L18 -> 1500000 | P18: =N18+O18 -> 0 | Q18: =D18+G18+J18+M18+P18 -> 3225000
A19: 09/2025 | B19: 800000 | C19: 3250000 | D19: =B19+C19 -> 4050000 | E19: 100000 | F19: 10684000 | G19: =E19+F19 -> 10784000 | H19: 1400000 | J19: =H19+I19 -> 1400000 | K19: 2000000 | M19: =K19+L19 -> 2000000 | N19: 500000 | P19: =N19+O19 -> 500000 | Q19: =D19+G19+J19+M19+P19 -> 18734000
A20: 10/2025 | B20: 2300000 | C20: 720000 | D20: =B20+C20 -> 3020000 | E20: 1500000 | G20: =E20+F20 -> 1500000 | H20: 2000000 | I20: 2000000 | J20: =H20+I20 -> 4000000 | K20: 3300000 | L20: 2155000 | M20: =K20+L20 -> 5455000 | P20: =N20+O20 -> 0 | Q20: =D20+G20+J20+M20+P20 -> 13975000
A21: 11/2025 | B21: 924000 | C21: 633000 | D21: =B21+C21 -> 1557000 | G21: =E21+F21 -> 0 | H21: 23086000 | I21: 30000000 | J21: =H21+I21 -> 53086000 | L21: 5214000 | M21: =K21+L21 -> 5214000 | N21: 698000 | P21: =N21+O21 -> 698000 | Q21: =D21+G21+J21+M21+P21 -> 60555000
A22: 12/2025 | D22: =B22+C22 -> 0 | G22: =E22+F22 -> 0 | J22: =H22+I22 -> 0 | M22: =K22+L22 -> 0 | P22: =N22+O22 -> 0 | Q22: =D22+G22+J22+M22+P22 -> 0
A23: TỔNG | B23: =SUM(B11:B22) -> 35224000 | C23: =SUM(C11:C22) -> 10266000 | D23: =SUM(D11:D22) -> 45490000 | E23: =SUM(E11:E22) -> 5800000 | F23: =SUM(F11:F22) -> 15277500 | G23: =SUM(G11:G22) -> 21077500 | H23: =SUM(H11:H22) -> 41086000 | I23: =SUM(I11:I22) -> 32000000 | ... Q23: =SUM(Q11:Q22) -> 1.838905e+08
A25: TP. TỔ CHỨC | H25: THỦ QUỸ | L25: NGƯỜI LẬP

Sheet KHEN THƯỞNG
A3: TỔNG CÔNG TY ĐẦU TƯ | F3: CỘNG HÒA XÃ HỘI CHỦ NGHĨA VIỆT NAM
A4: PHÁT TRIỂN ĐÔ THỊ - CTCP | F4: Độc Lập - Tự Do - Hạnh Phúc
A7: TỔNG HỢP KHEN THƯỞNG NĂM 2025
A9: STT | B9: Số QĐ | C9: NGÀY THÁNG | D9: HỌ TÊN; TẬP THỂ | E9: BỘ PHẬN | F9: THÀNH TÍCH | G9: MỨC KHEN THƯỞNG | H9: ĐIỂM THƯỞNG | I9: GHI CHÚ
A10: 1 | B10: 116 | C10: 45709 | D10: Nguyễn Trọng Hội | E10: Nhân viên bảo vệ - PTCHC | F10: Vào hồi 17h ngày 22/01/2025 tại vị trí (cổng 3) phân xưởng 1; Tổ bảo vệ kiểm tra hành lý trước khi công nhân giao ca ra về, phát hiện Ông Dương lấy 1 bó dây rút điện (70 cái) sử dụng vào mục đích cá nhân, tâng vật đã được lập văn bản và thu hồi trả lại PX (Theo quy định tiền thưởng bằng 30% giá trị tài sản bị thất thoát, xong do giá trị tài sản rất thấp, để động viên khích lệ CBCNV, cty vận dụng tiền thưởng bằng 30% số tiền xử lý người vi phạm) | G10: 300000 | H10: 5
A11: 2 | B11: 232 | C11: 45741 | D11: Phó GĐ Điều hành + BGĐ PXSX1 | E11: Phó GĐ Điều hành + BGĐ PXSX1 | G11: 14000000
B12: 232 | C12: 45741 | D12: Phó GĐ Điều hành + BGĐ PXSX2 | E12: Phó GĐ Điều hành + BGĐ PXSX2 | G12: 15000000
A13: 3 | B13: 171 | C13: 45720 | D13: Tập thể bộ phận dây chuyền và lò nung | E13: Tập thể CBCNV ca 2A ngày 26/02/2025 DC5-PXSX2 | F13: Đạt mục tiêu khen thưởng theo thông báo về việc thi đua lập thành tích trong sản xuất Dây chuyền 5 của Ban Giám đốc PXSX2 ngày 21/2/2025 | G13: 2000000 | J13: k đc tính
D14: Tập thể bộ phận mài và bao gói | G14: 3000000 | J14: k đc tính
D15: Tập thể bộ phận cơ điện và cơ lý đi ca | G15: 500000 | J15: k đc tính
A16: 4 | B16: 172 | C16: 45720 | D16: Tập thể bộ phận dây chuyền và lò nung | E16: Tập thể CBCNV ca 1B ngày 23/02/2025 DC5-PXSX2 | F16: Đạt mục tiêu khen thưởng theo thông báo về việc thi đua lập thành tích trong sản xuất Dây chuyền 5 của Ban Giám đốc PXSX2 ngày 21/2/2025 | G16: 2000000 | J16: k đc tính
D17: Tập thể bộ phận mài và bao gói | G17: 3000000 | J17: k đc tính
D18: Tập thể bộ phận cơ điện và cơ lý đi ca | G18: 500000 | J18: k đc tính
B19: 373 | C19: 45791 | D19: Tập thể đội sửa chữa | E19: Ban đầu tư và khai thác | F19: Tập thể đội sửa chữa đã cải tiến, gia công "Khuôn ép lốp đặc xe nâng" thực hiện sửa chữa và thay thế tại phân xưởng, thay cho việc phải vận chuyển đi thay bên ngoài, vừa rút ngắn thời gian phương tiện lưu xưởng, đồng thời tiết kiệm chi phí cho nhà máy, mang lại hiệu xuất kinh doanh | G19: 10000000
D20: Vũ Xuân Tuấn | E20: Trợ lý TGĐ - Phụ trách đội xe | H20: 3
D21: Phạm Văn Thiện | E21: Đội trưởng | G21: 5000000
A22: 1 | B22: 448 | C22: 45815 | D22: Tập thể nghiền sấy phun PXSX1 | E22: Tập thể nghiền sấy phun PXSX1 | F22: Tập thể bộ phận nghiền sấy phun PXSX1 đã chủ động khắc phục mọi khó khăn về thời tiết và thiếu hụt nguồn nhân lực nhưng vẫn chủ động đáp ứng nguồn nguyên liệu phục vụ sản xuất của phân xưởng | G22: 1000000
A23: 2 | D23: Phan Văn Thắng | E23: Phó bộ phận sấy phun PXSX1 | G23: 500000 | H23: 5
A24: 3 | B24: 537 | C24: 45831 | D24: Tập thể bộ phận sơ chế | E24: Tập thể bộ phận sơ chế | F24: Tập thể bộ phận sơ chế( Tổ phục vụ xuất hàng) và các cá nhân bộ phận cơ điện PXSX1 đã chủ động khắc phục mọi khó khăn về thời tiết và thiếu hụt nhân lực nhưng vẫn chủ động đáp ứng công tác đảm bảo phục vụ sản xuất của phân xưởng | G24: 1000000
A25: 4 | D25: Lê Bá Long | E25: Tổ trưởng tổ PVXH | G25: 300000 | H25: 3
A26: 5 | D26: Lê Viết Hùng | E26: NV cơ điện PX1 | G26: 300000 | H26: 3
A27: 6 | D27: Nguyễn Đình Vũ | E27: NV cơ điện PX1 | G27: 300000 | H27: 3
A28: 17 | B28: 755 | C28: 45896 | D28: Tổ phục vụ xuất hàng | E28: Phòng kế toán | F28: Khen thưởng đối với tập thể tổ phục vụ xuất hàng, Phòng kế toán. Vì đã có thành tích đột xuất trong quá trình thực hiện nhiệm vụ xuất hàng cho nhà phân phối tại tại thời điểm điễn biến cơn bão số 5 (Kajiki) vào ngày 25/08/2025 | G28: 5000000
A29: 18 | B29: 756 | C29: 45896 | D29: Đỗ Ngọc Toàn | E29: PP Phòng tổ chức | F29: Khen thưởng đối với các cá nhân vì đã có thành tích đột xuất trong quá trình thực hiện nhiệm vụ phòng chống bão số 5 (Kajiki) ngày 24/08/2025 | G29: 300000 | H29: 5
A30: 19 | D30: Phạm Văn Lực | E30: Chuyên viên Phòng tổ chức | G30: 300000 | H30: 5
A31: 20 | D31: Nguyễn Anh Hải | E31: PP Phòng khai thác | G31: 300000 | H31: 5
A32: 21 | D32: Bùi Sỹ Quang | E32: TBP ngiền SP PX1 | G32: 300000 | H32: 5
A33: 22 | D33: Lê Xuân Lộc | E33: Giám đốc mỏ | G33: 300000 | H33: 5
A34: 23 | D34: Đỗ Văn Duyên | E34: Tổ QC | G34: 300000 | H34: 5
A35: 24 | D35: Nguyễn Hoàng Anh | E35: Tổ QC | G35: 300000 | H35: 5
A36: 25 | D36: Trần Công Đua | E36: Bảo vệ | G36: 300000 | H36: 5
A37: 26 | D37: Nguyễn Văn Thìn | E37: PXCBNL | G37: 300000 | H37: 5
A38: 27 | D38: Hoàng Đình Cương | E38: PXCBNL | G38: 300000 | H38: 5
A39: 28 | D39: Lê Văn Hưng | E39: PXCBNL | G39: 300000 | H39: 5
A40: 29 | D40: Lê Đình Hưng | E40: PXCBNL | G40: 300000 | H40: 5
A41: 30 | C41: 45922 | D41: Phòng kỹ thuật | E41: Phân xưởng 1 | F41: Vì đã có thành tích trong quá trình xử lý hệ thống làm mát, đảm bảo hoạt động của lò đốt dăm gỗ, đáp ứng nhu cầu sản xuất vào ngày 20/09/2025. | G41: 2000000
A42: 31 | C42: 45939 | E42: Phân xưởng 1 | F42: Vì đã có thành tích hoàn thành tốt nhiệm vụ thi công lò than mới, vận hành thử nghiệm đảm bảo an toàn, đáp ứng yêu cầu kỹ thuật, phục vụ sản xuất cho phân xưởng. | G42: 30000000
A43: 32 | C43: 45939 | E43: Phân xưởng 2 | F43: Vì đã có thành tích hoàn thành tốt nhiệm vụ trong quá trình cải tạo máy đóng bao để sản xuất thành công gạch khổ lớn (600 x 1200) và (1000 x 1000) từ máy đóng bao khổ (800 x 800) đảm bảo hoàn thành kế hoạch sản xuất của Tổng công ty. | G43: 30000000
A44: 33 | C44: 45939 | D44: Phòng kỹ thuật | E44: Phân xưởng 2 | F44: Vì đã có thành tích hoàn thành tốt nhiệm vụ trong quá trình cải tạo máy đóng bao để sản xuất thành công gạch khổ lớn (600 x 1200) và (1000 x 1000) từ máy đóng bao khổ (800 x 800) đảm bảo hoàn thành kế hoạch sản xuất của Tổng công ty. | G44: 15000000
A45: 34 | C45: 45939 | D45: Trần Quốc Tuấn | E45: GĐ Phân xưởng 2 | F45: Vì đã có thành tích hoàn thành xuất sắc nhiệm vụ chỉ đạo cải tiến hệ thống máy đóng bao và tổ chức chuyển đổi sản xuất dòng gạch khổ lớn (600 x 1200) và (1000 x 1000) đảm bảo hoàn thành kế hoạch sản xuất của Tổng công ty. | G45: 5000000
...

Sheet Danh sách
A2: DANH SÁCH TỔ XE NÂNG PHỤC VỤ XUẤT HÀNG
A4: STT | B4: MÃ NV | C4: HỌ TÊN | D4: NGÀY SINH | E4: CHỨC VỤ
A5: 1 | B5: NV2213 | C5: Lê Bá Triệu | D5: 30529 | E5: Nhóm trưởng xe nâng
A6: 2 | B6: NV0760 | C6: Đỗ Đức Hùng | D6: 27218 | E6: Nhân viên Lái xe nâng
A7: 3 | B7: NV0757 | C7: Lê Anh Tuấn | D7: 31568 | E7: Nhân viên Lái xe nâng
A8: 4 | B8: NV1871 | C8: Viên Đình Khang | D8: 35098 | E8: Nhân viên Lái xe nâng
A9: 5 | B9: NV1296 | C9: Nguyễn Đăng Ánh | D9: 29421 | E9: Nhân viên Lái xe nâng
A10: 6 | B10: NV1236 | C10: Đỗ Xuân Nam | D10: 30994 | E10: Nhân viên Lái xe nâng
A11: 7 | B11: NV0758 | C11: Đặng Minh Yên | D11: 30127 | E11: Nhân viên Lái xe nâng
A12: 8 | B12: NV0386 | C12: Lê Đình Tuấn | D12: 29514 | E12: Nhân viên Lái xe nâng
A13: 9 | B13: NV1057 | C13: Nguyễn Tuấn Tâm | D13: 33888 | E13: Nhân viên Lái xe nâng
A14: 10 | B14: NV0377 | C14: Lê Quang Việt | D14: 30446 | E14: Nhân viên Lái xe nâng
A15: 11 | B15: NV0382 | C15: Đỗ Văn Khánh | D15: 33374 | E15: Nhân viên Lái xe nâng
A16: 12 | B16: NV2494 | C16: Hoàng Ngọc Huy | D16: 34820 | E16: Nhân viên Lái xe nâng
... A19: 15 | B19: NV0389 | C19: Nguyễn Bá Dũng | D19: 29143 | E19: Nhân viên Lái xe nâng
A22: DANH SÁCH LÁI MÁY XÚC LẬT PXSX1
A24: STT | B24: MÃ NV | C24: HỌ TÊN | D24: NGÀY SINH | E24: CHỨC VỤ
A25: 1 | B25: NV0131 | C25: Nguyễn Viết Thanh | D25: 31253 | E25: Nhóm trưởng xúc lật
A26: 2 | B26: NV0135 | C26: Nguyễn Khắc Thành | D26: 32572 | E26: Xúc lật
A27: 3 | B27: NV4864 | C27: Hoàng Xuân Tùng | D27: 33851 | E27: Xúc lật
A28: 4 | B28: NV1618 | C28: Nguyễn Khắc Thảo | D28: 34495 | E28: Xúc lật
A32: DANH SÁCH TỔ XE NÂNG PHỤC VỤ XUẤT HÀNG
A34: STT | B34: MÃ NV | C34: HỌ TÊN | D34: NGÀY SINH | E34: CHỨC VỤ
A35: 1 | B35: NV0760 | C35: Đỗ Đức Hùng | D35: 27218 | E35: Nhân viên Lái xe nâng
A36: 2 | B36: NV0757 | C36: Lê Anh Tuấn | D36: 31568 | E36: Nhân viên Lái xe nâng
A37: 3 | B37: NV1871 | C37: Viên Đình Khang | D37: 35098 | E37: Nhân viên Lái xe nâng
A38: 4 | B38: NV1296 | C38: Nguyễn Đăng Ánh | D38: 29421 | E38: Nhân viên Lái xe nâng
A39: 5 | B39: NV1236 | C39: Đỗ Xuân Nam | D39: 30994 | E39: Nhân viên Lái xe nâng
A40: 6 | B40: NV0758 | C40: Đặng Minh Yên | D40: 30127 | E40: Nhân viên Lái xe nâng
A41: 7 | B41: NV0386 | C41: Lê Đình Tuấn | D41: 29514 | E41: Nhân viên Lái xe nâng
A42: 8 | B42: NV0377 | C42: Lê Quang Việt | D42: 30446 | E42: Nhân viên Lái xe nâng
A43: 9 | B43: NV0382 | C43: Đỗ Văn Khánh | D43: 33374 | E43: Nhân viên Lái xe nâng
A44: 10 | B44: NV4328 | C44: Nguyễn Viết Thiện | D44: 31472 | E44: Nhân viên Lái xe nâng
A45: 11 | B45: NV0389 | C45: Nguyễn Bá Dũng | D45: 29143 | E45: Nhân viên Lái xe nâng
A46: 12 | B46: NV5522 | C46: Phạm Thế Luyến | D46: 34279 | E46: Nhân viên Lái xe nâng
A47: 13 | B47: NV5529 | C47: Vũ Đình Hải | D47: 33810 | E47: Nhân viên Lái xe nâng
A48: 14

Sheet Tổng hợp điểm phạt
A2: TỔNG CÔNG TY ĐẦU TƯ | H2: CỘNG HÒA XÃ HỘI CHỦ NGHĨA VIỆT NAM
A3: PHÁT TRIỂN ĐÔ THỊ - CTCP | H3: Độc Lập - Tự Do - Hạnh Phúc
H4: Thanh Hóa ngày 05 tháng 12 năm 2025
A5: TỔNG HỢP ĐIỂM PHẠT HÀNG THÁNG2025
A7: TT | B7: Họ và tên | C7: Mã nhân viên | D7: Bộ phận | E7: Tháng 1 | F7: Tháng 2 | G7: Tháng 3 | H7: Tháng 4 | I7: Tháng 5 | J7: Tháng 6 | K7: Tháng 7 | L7: Tháng 8 | M7: Tháng 9 | N7: Tháng 10 | O7: Tháng 11 | P7: Tháng 12 | Q7: Tổng
A8: 1 | B8: Lê Văn Chính | C8: NV2579 | D8: NV Tổ bảo vệ Phòng TC | F8: 15 | M8: 5 | Q8: =SUM(E8,F8:P8) -> 20
A9: 2 | B9: Hoàng Ngọc Dương | C9: NV4119 | D9: NV Thủ kho Phòng Kế toán | F9: 20 | Q9: =SUM(E9,F9:P9) -> 20
A10: 3 | B10: Đỗ Đức Nam | C10: NV3323 | D10: NV QC Ban kiểm soát | F10: 10 | Q10: =SUM(E10,F10:P10) -> 10
A11: 4 | B11: Viên Đình Khang | C11: NV1871 | D11: Lái xe nâng - Tổ PVXH | F11: 18 | Q11: =SUM(E11,F11:P11) -> 18
A12: 5 | B12: Nguyễn Xuân Thuỷ | C12: NV5019 | D12: NV lái xe mỏ - Phòng khai thác | F12: 20 | Q12: =SUM(E12,F12:P12) -> 20
A13: 6 | B13: Lê Bá Cẩn | C13: NV5273 | D13: NV lái xe mỏ - Phòng khai thác | F13: 5 | Q13: =SUM(E13,F13:P13) -> 5
A14: 7 | B14: Nguyễn Duy Dương | C14: NV4640 | D14: CN Dây chuyền - BP nhiên liệu và gia công bán thành phẩm | F14: 20 | Q14: =SUM(E14,F14:P14) -> 20
A15: 8 | B15: Phạm Văn Sơn | C15: NV4187 | D15: Công nhân Lái xe nâng - DC5 - PXSX2 | F15: 30 | Q15: =SUM(E15,F15:P15) -> 30
A16: 9 | B16: Nguyễn Huy Toàn | C16: NV0695 | D16: NV Thủ kho Phòng Kế toán | G16: 8 | Q16: =SUM(E16,F16:P16) -> 8
A17: 10 | B17: Lê Đình Tuấn | C17: NV2486 | D17: NV Tổ bảo vệ Phòng TC | G17: 5 | M17: 13 | Q17: =SUM(E17,F17:P17) -> 18
A18: 11 | B18: Nguyễn Thị Bích Hường | C18: NV0041 | D18: GĐ ban kinh doanh | G18: 2 | H18: 3 | Q18: =SUM(E18,F18:P18) -> 5
A19: 12 | B19: Đỗ Thị Hằng | C19: NV1278 | D19: Nhân viên điều phối vùng 8+9 - Ban kinh doanh | G19: 5 | Q19: =SUM(E19,F19:P19) -> 5
A20: 13 | B20: Nguyễn Văn Tuấn | C20: NV5394 | D20: NV lái xe mỏ - Phòng khai thác | G20: 15 | H20: 5 | Q20: =SUM(E20,F20:P20) -> 20
A21: 14 | B21: Lê Bá Triệu | C21: NV2213 | D21: Lái xe nâng - Tổ PVXH | G21: 15 | Q21: =SUM(E21,F21:P21) -> 15
A22: 15 | B22: Hoàng Huy Tuấn | C22: NV0756 | D22: Tổ phó hậu cần nội vụ , PXSX1 | G22: 5 | Q22: =SUM(E22,F22:P22) -> 5
A23: 16 | B23: Nguyễn Viết Thanh | C23: NV0131 | D23: NT xúc lật | G23: 5 | H23: 3 | M23: 10 | N23: 20 | Q23: =SUM(E23,F23:P23) -> 38
A24: 17 | B24: Nguyễn Khắc Thành | C24: NV0135 | D24: NT xúc lật | G24: 5 | M24: 10 | Q24: =SUM(E24,F24:P24) -> 15
A25: 18 | B25: Nguyễn Khắc Thảo | C25: NV1618 | D25: NT xúc lật | G25: 5 | M25: 10 | Q25: =SUM(E25,F25:P25) -> 15
A26: 19 | B26: Lê Duy Hùng | C26: NV0659 | D26: Tổ trưởng DC gia công ca A - BP DC gia công và lò nung DC5 - PXSX2 | G26: 2 | Q26: =SUM(E26,F26:P26) -> 2
A27: 20 | B27: Nguyễn Thái Thuận | C27: NV0486 | D27: Vận hành máy đóng bao ca 1A DC6 PXSX2 | G27: 5 | Q27: =SUM(E27,F27:P27) -> 5
A28: 21 | B28: Nguyễn Trung Kiên | C28: NV4623 | D28: Quản lý dây chuyền mài PXSX2 | G28: 3 | Q28: =SUM(E28,F28:P28) -> 3
A29: 22 | B29: Trần Thanh Hải | C29: NV3449 | D29: Tổ trưởng mài ca B PXSX2 | G29: 6 | Q29: =SUM(E29,F29:P29) -> 6
A30: 23 | B30: Văn Tiến Đức | C30: NV4557 | D30: Công nhân vận hành bể nước thải PXSX2 | G30: 20 | Q30: =SUM(E30,F30:P30) -> 20
A31: 24 | B31: Lưu Đăng Khoa | C31: NV5216 | D31: Nhân viên test mẫu, BP Công nghệ PXSX2 | G31: 20 | Q31: =SUM(E31,F31:P31) -> 20
A32: 25 | B32: Nguyễn Sỹ Tư | C32: NV3086 | D32: Nhân viên test mẫu, BP Công nghệ PXSX2 | G32: 7 | Q32: =SUM(E32,F32:P32) -> 7
A33: 26 | B33: Vũ Đình Hoàng | C33: NV0215 | D33: CBKT, BP Công nghệ PXSX2 | G33: 3 | H33: 3 | I33: 5 | K33: 5 | L33: 5 | Q33: =SUM(E33,F33:P33) -> 21
A34: 27 | B34: Nguyễn Văn Dương | C34: NV0005 | D34: PGĐ - Ban kinh doanh | H34: 2 | Q34: =SUM(E34,F34:P34) -> 2
A35: 28 | B35: Lê Thị Thanh Thuý | C35: NV4081 | D35: NV - Phòng kế toán | H35: 8 | Q35: =SUM(E35,F35:P35) -> 8
A36: 29 | B36: Trần Thị Hương | C36: NV0027 | D36: Ban kinh doanh | H36: 3 | Q36: =SUM(E36,F36:P36) -> 3
A37: 30 | B37: Nguyễn Thị Biên | C37: NV0036 | D37: Nhân viên hỗ trợ thị trường - Ban kinh doanh | H37: 39 | Q37: =SUM(E37,F37:P37) -> 39
A38: 31 | B38: Nguyễn Thị Hà | C38: NV2352 | D38: Nhân viên hỗ trợ thị trường - Ban kinh doanh | H38: 3 | Q38: =SUM(E38,F38:P38) -> 3
A39: 32 | B39: Lê Hữu Mạnh | C39: NV0861 | D39: Nhân viên hỗ trợ thị trường - Ban kinh doanh | H39: 3 | Q39: =SUM(E39,F39:P39) -> 3
A40: 33 | B40: Lê Tuấn Anh | C40: NV0058 | D40: Phó phòng sản xuất - PXSX1 | H40: 5 | Q40: =SUM(E40,F40:P40) -> 5
A41: 34 | B41: Hoàng Minh Hà | C41: NV0450 | D41: Phó giám đốc PXSX1 | H41: 5 | N41: 5 | Q41: =SUM(E41,F41:P41) -> 10
A42: 35 | B42: Nguyễn Văn Thanh | C42: NV0765 | D42: Trưởng phòng sản xuất PXSX1 | H42: 5 | Q42: =SUM(E42,F42:P42) -> 5
...
